nohup: ignoring input
Traceback (most recent call last):
  File "C:\Users\francisco.contreras\AppData\Local\Programs\Python\Python313\Lib\site-packages\sqlalchemy\engine\base.py", line 146, in __init__
    self._dbapi_connection = engine.raw_connection()
                             ~~~~~~~~~~~~~~~~~~~~~^^
  File "C:\Users\francisco.contreras\AppData\Local\Programs\Python\Python313\Lib\site-packages\sqlalchemy\engine\base.py", line 3298, in raw_connection
    return self.pool.connect()
           ~~~~~~~~~~~~~~~~~^^
  File "C:\Users\francisco.contreras\AppData\Local\Programs\Python\Python313\Lib\site-packages\sqlalchemy\pool\base.py", line 449, in connect
    return _ConnectionFairy._checkout(self)
           ~~~~~~~~~~~~~~~~~~~~~~~~~~^^^^^^
  File "C:\Users\francisco.contreras\AppData\Local\Programs\Python\Python313\Lib\site-packages\sqlalchemy\pool\base.py", line 1264, in _checkout
    fairy = _ConnectionRecord.checkout(pool)
  File "C:\Users\francisco.contreras\AppData\Local\Programs\Python\Python313\Lib\site-packages\sqlalchemy\pool\base.py", line 713, in checkout
    rec = pool._do_get()
  File "C:\Users\francisco.contreras\AppData\Local\Programs\Python\Python313\Lib\site-packages\sqlalchemy\pool\impl.py", line 179, in _do_get
    with util.safe_reraise():
         ~~~~~~~~~~~~~~~~~^^
  File "C:\Users\francisco.contreras\AppData\Local\Programs\Python\Python313\Lib\site-packages\sqlalchemy\util\langhelpers.py", line 146, in __exit__
    raise exc_value.with_traceback(exc_tb)
  File "C:\Users\francisco.contreras\AppData\Local\Programs\Python\Python313\Lib\site-packages\sqlalchemy\pool\impl.py", line 177, in _do_get
    return self._create_connection()
           ~~~~~~~~~~~~~~~~~~~~~~~^^
  File "C:\Users\francisco.contreras\AppData\Local\Programs\Python\Python313\Lib\site-packages\sqlalchemy\pool\base.py", line 390, in _create_connection
    return _ConnectionRecord(self)
  File "C:\Users\francisco.contreras\AppData\Local\Programs\Python\Python313\Lib\site-packages\sqlalchemy\pool\base.py", line 675, in __init__
    self.__connect()
    ~~~~~~~~~~~~~~^^
  File "C:\Users\francisco.contreras\AppData\Local\Programs\Python\Python313\Lib\site-packages\sqlalchemy\pool\base.py", line 901, in __connect
    with util.safe_reraise():
         ~~~~~~~~~~~~~~~~~^^
  File "C:\Users\francisco.contreras\AppData\Local\Programs\Python\Python313\Lib\site-packages\sqlalchemy\util\langhelpers.py", line 146, in __exit__
    raise exc_value.with_traceback(exc_tb)
  File "C:\Users\francisco.contreras\AppData\Local\Programs\Python\Python313\Lib\site-packages\sqlalchemy\pool\base.py", line 897, in __connect
    self.dbapi_connection = connection = pool._invoke_creator(self)
                                         ~~~~~~~~~~~~~~~~~~~~^^^^^^
  File "C:\Users\francisco.contreras\AppData\Local\Programs\Python\Python313\Lib\site-packages\sqlalchemy\engine\create.py", line 646, in connect
    return dialect.connect(*cargs, **cparams)
           ~~~~~~~~~~~~~~~^^^^^^^^^^^^^^^^^^^
  File "C:\Users\francisco.contreras\AppData\Local\Programs\Python\Python313\Lib\site-packages\sqlalchemy\engine\default.py", line 625, in connect
    return self.loaded_dbapi.connect(*cargs, **cparams)  # type: ignore[no-any-return]  # NOQA: E501
           ~~~~~~~~~~~~~~~~~~~~~~~~~^^^^^^^^^^^^^^^^^^^
  File "C:\Users\francisco.contreras\AppData\Local\Programs\Python\Python313\Lib\site-packages\psycopg2\__init__.py", line 135, in connect
    conn = _connect(dsn, connection_factory=connection_factory, **kwasync)
psycopg2.OperationalError: connection to server at "localhost" (::1), port 5432 failed: Connection refused (0x0000274D/10061)
	Is the server running on that host and accepting TCP/IP connections?
connection to server at "localhost" (127.0.0.1), port 5432 failed: Connection refused (0x0000274D/10061)
	Is the server running on that host and accepting TCP/IP connections?


The above exception was the direct cause of the following exception:

Traceback (most recent call last):
  File "<frozen runpy>", line 189, in _run_module_as_main
  File "<frozen runpy>", line 112, in _get_module_details
  File "C:\Users\francisco.contreras\Desktop\jupyter-projects\notebooks\app.py", line 31, in <module>
    Base.metadata.create_all(engine)
    ~~~~~~~~~~~~~~~~~~~~~~~~^^^^^^^^
  File "C:\Users\francisco.contreras\AppData\Local\Programs\Python\Python313\Lib\site-packages\sqlalchemy\sql\schema.py", line 5925, in create_all
    bind._run_ddl_visitor(
    ~~~~~~~~~~~~~~~~~~~~~^
        ddl.SchemaGenerator, self, checkfirst=checkfirst, tables=tables
        ^^^^^^^^^^^^^^^^^^^^^^^^^^^^^^^^^^^^^^^^^^^^^^^^^^^^^^^^^^^^^^^
    )
    ^
  File "C:\Users\francisco.contreras\AppData\Local\Programs\Python\Python313\Lib\site-packages\sqlalchemy\engine\base.py", line 3248, in _run_ddl_visitor
    with self.begin() as conn:
         ~~~~~~~~~~^^
  File "C:\Users\francisco.contreras\AppData\Local\Programs\Python\Python313\Lib\contextlib.py", line 141, in __enter__
    return next(self.gen)
  File "C:\Users\francisco.contreras\AppData\Local\Programs\Python\Python313\Lib\site-packages\sqlalchemy\engine\base.py", line 3238, in begin
    with self.connect() as conn:
         ~~~~~~~~~~~~^^
  File "C:\Users\francisco.contreras\AppData\Local\Programs\Python\Python313\Lib\site-packages\sqlalchemy\engine\base.py", line 3274, in connect
    return self._connection_cls(self)
           ~~~~~~~~~~~~~~~~~~~~^^^^^^
  File "C:\Users\francisco.contreras\AppData\Local\Programs\Python\Python313\Lib\site-packages\sqlalchemy\engine\base.py", line 148, in __init__
    Connection._handle_dbapi_exception_noconnection(
    ~~~~~~~~~~~~~~~~~~~~~~~~~~~~~~~~~~~~~~~~~~~~~~~^
        err, dialect, engine
        ^^^^^^^^^^^^^^^^^^^^
    )
    ^
  File "C:\Users\francisco.contreras\AppData\Local\Programs\Python\Python313\Lib\site-packages\sqlalchemy\engine\base.py", line 2439, in _handle_dbapi_exception_noconnection
    raise sqlalchemy_exception.with_traceback(exc_info[2]) from e
  File "C:\Users\francisco.contreras\AppData\Local\Programs\Python\Python313\Lib\site-packages\sqlalchemy\engine\base.py", line 146, in __init__
    self._dbapi_connection = engine.raw_connection()
                             ~~~~~~~~~~~~~~~~~~~~~^^
  File "C:\Users\francisco.contreras\AppData\Local\Programs\Python\Python313\Lib\site-packages\sqlalchemy\engine\base.py", line 3298, in raw_connection
    return self.pool.connect()
           ~~~~~~~~~~~~~~~~~^^
  File "C:\Users\francisco.contreras\AppData\Local\Programs\Python\Python313\Lib\site-packages\sqlalchemy\pool\base.py", line 449, in connect
    return _ConnectionFairy._checkout(self)
           ~~~~~~~~~~~~~~~~~~~~~~~~~~^^^^^^
  File "C:\Users\francisco.contreras\AppData\Local\Programs\Python\Python313\Lib\site-packages\sqlalchemy\pool\base.py", line 1264, in _checkout
    fairy = _ConnectionRecord.checkout(pool)
  File "C:\Users\francisco.contreras\AppData\Local\Programs\Python\Python313\Lib\site-packages\sqlalchemy\pool\base.py", line 713, in checkout
    rec = pool._do_get()
  File "C:\Users\francisco.contreras\AppData\Local\Programs\Python\Python313\Lib\site-packages\sqlalchemy\pool\impl.py", line 179, in _do_get
    with util.safe_reraise():
         ~~~~~~~~~~~~~~~~~^^
  File "C:\Users\francisco.contreras\AppData\Local\Programs\Python\Python313\Lib\site-packages\sqlalchemy\util\langhelpers.py", line 146, in __exit__
    raise exc_value.with_traceback(exc_tb)
  File "C:\Users\francisco.contreras\AppData\Local\Programs\Python\Python313\Lib\site-packages\sqlalchemy\pool\impl.py", line 177, in _do_get
    return self._create_connection()
           ~~~~~~~~~~~~~~~~~~~~~~~^^
  File "C:\Users\francisco.contreras\AppData\Local\Programs\Python\Python313\Lib\site-packages\sqlalchemy\pool\base.py", line 390, in _create_connection
    return _ConnectionRecord(self)
  File "C:\Users\francisco.contreras\AppData\Local\Programs\Python\Python313\Lib\site-packages\sqlalchemy\pool\base.py", line 675, in __init__
    self.__connect()
    ~~~~~~~~~~~~~~^^
  File "C:\Users\francisco.contreras\AppData\Local\Programs\Python\Python313\Lib\site-packages\sqlalchemy\pool\base.py", line 901, in __connect
    with util.safe_reraise():
         ~~~~~~~~~~~~~~~~~^^
  File "C:\Users\francisco.contreras\AppData\Local\Programs\Python\Python313\Lib\site-packages\sqlalchemy\util\langhelpers.py", line 146, in __exit__
    raise exc_value.with_traceback(exc_tb)
  File "C:\Users\francisco.contreras\AppData\Local\Programs\Python\Python313\Lib\site-packages\sqlalchemy\pool\base.py", line 897, in __connect
    self.dbapi_connection = connection = pool._invoke_creator(self)
                                         ~~~~~~~~~~~~~~~~~~~~^^^^^^
  File "C:\Users\francisco.contreras\AppData\Local\Programs\Python\Python313\Lib\site-packages\sqlalchemy\engine\create.py", line 646, in connect
    return dialect.connect(*cargs, **cparams)
           ~~~~~~~~~~~~~~~^^^^^^^^^^^^^^^^^^^
  File "C:\Users\francisco.contreras\AppData\Local\Programs\Python\Python313\Lib\site-packages\sqlalchemy\engine\default.py", line 625, in connect
    return self.loaded_dbapi.connect(*cargs, **cparams)  # type: ignore[no-any-return]  # NOQA: E501
           ~~~~~~~~~~~~~~~~~~~~~~~~~^^^^^^^^^^^^^^^^^^^
  File "C:\Users\francisco.contreras\AppData\Local\Programs\Python\Python313\Lib\site-packages\psycopg2\__init__.py", line 135, in connect
    conn = _connect(dsn, connection_factory=connection_factory, **kwasync)
sqlalchemy.exc.OperationalError: (psycopg2.OperationalError) connection to server at "localhost" (::1), port 5432 failed: Connection refused (0x0000274D/10061)
	Is the server running on that host and accepting TCP/IP connections?
connection to server at "localhost" (127.0.0.1), port 5432 failed: Connection refused (0x0000274D/10061)
	Is the server running on that host and accepting TCP/IP connections?

(Background on this error at: https://sqlalche.me/e/20/e3q8)
