 * Serving Flask app 'app'
 * Debug mode: on
WARNING: This is a development server. Do not use it in a production deployment. Use a production WSGI server instead.
 * Running on all addresses (0.0.0.0)
 * Running on http://127.0.0.1:8083
 * Running on http://172.19.78.144:8083
Press CTRL+C to quit
 * Restarting with stat
 * Debugger is active!
 * Debugger PIN: 828-147-444
127.0.0.1 - - [22/May/2025 17:22:05] "GET /favicon.ico HTTP/1.1" 404 -
127.0.0.1 - - [22/May/2025 17:22:07] "GET /tablas/ HTTP/1.1" 200 -
127.0.0.1 - - [22/May/2025 17:22:12] "GET /tablas/generar_tabla HTTP/1.1" 500 -
127.0.0.1 - - [22/May/2025 17:23:40] "GET /tablas/generar_tabla HTTP/1.1" 200 -
127.0.0.1 - - [22/May/2025 17:27:17] "GET /tablas/descargar/Publica%20(3)%20(4).bpmn HTTP/1.1" 500 -
Traceback (most recent call last):
  File "C:\Users\francisco.contreras\Desktop\jupyter-projects\jbpm-data\Lib\site-packages\flask\app.py", line 1536, in __call__
    return self.wsgi_app(environ, start_response)
           ~~~~~~~~~~~~~^^^^^^^^^^^^^^^^^^^^^^^^^
  File "C:\Users\francisco.contreras\Desktop\jupyter-projects\jbpm-data\Lib\site-packages\flask\app.py", line 1514, in wsgi_app
    response = self.handle_exception(e)
  File "C:\Users\francisco.contreras\Desktop\jupyter-projects\jbpm-data\Lib\site-packages\flask\app.py", line 1511, in wsgi_app
    response = self.full_dispatch_request()
  File "C:\Users\francisco.contreras\Desktop\jupyter-projects\jbpm-data\Lib\site-packages\flask\app.py", line 919, in full_dispatch_request
    rv = self.handle_user_exception(e)
  File "C:\Users\francisco.contreras\Desktop\jupyter-projects\jbpm-data\Lib\site-packages\flask\app.py", line 917, in full_dispatch_request
    rv = self.dispatch_request()
  File "C:\Users\francisco.contreras\Desktop\jupyter-projects\jbpm-data\Lib\site-packages\flask\app.py", line 902, in dispatch_request
    return self.ensure_sync(self.view_functions[rule.endpoint])(**view_args)  # type: ignore[no-any-return]
           ~~~~~~~~~~~~~~~~~~~~~~~~~~~~~~~~~~~~~~~~~~~~~~~~~~~~^^^^^^^^^^^^^
  File "C:\Users\francisco.contreras\Desktop\jupyter-projects\notebooks\MAYA-Modular\app\tablas_busqueda.py", line 27, in descargar_archivo
    for root, dirs, files in os.walk(ARCHIVOS_BASE_DIR):
                                     ^^^^^^^^^^^^^^^^^
NameError: name 'ARCHIVOS_BASE_DIR' is not defined
127.0.0.1 - - [22/May/2025 17:27:17] "GET /tablas/descargar/Publica%20(3)%20(4).bpmn?__debugger__=yes&cmd=resource&f=style.css HTTP/1.1" 200 -
127.0.0.1 - - [22/May/2025 17:27:17] "GET /tablas/descargar/Publica%20(3)%20(4).bpmn?__debugger__=yes&cmd=resource&f=debugger.js HTTP/1.1" 200 -
127.0.0.1 - - [22/May/2025 17:27:17] "GET /tablas/descargar/Publica%20(3)%20(4).bpmn?__debugger__=yes&cmd=resource&f=console.png&s=3hBY89Xc4iyvkAgdjVDN HTTP/1.1" 200 -
127.0.0.1 - - [22/May/2025 17:27:18] "GET /tablas/descargar/Publica%20(3)%20(4).bpmn?__debugger__=yes&cmd=resource&f=console.png HTTP/1.1" 200 -
 * Detected change in 'C:\\Users\\francisco.contreras\\Desktop\\jupyter-projects\\notebooks\\MAYA-Modular\\app\\.ipynb_checkpoints\\tablas_busqueda-checkpoint.py', reloading
Exception in thread Thread-1 (serve_forever):
 * Restarting with stat
 * Debugger is active!
 * Debugger PIN: 828-147-444
127.0.0.1 - - [22/May/2025 17:27:28] "GET /tablas/ HTTP/1.1" 200 -
127.0.0.1 - - [22/May/2025 17:27:29] "GET /tablas/generar_tabla HTTP/1.1" 200 -
127.0.0.1 - - [22/May/2025 17:27:30] "GET /tablas/descargar/Publica%20(3)%20(4).bpmn HTTP/1.1" 404 -
127.0.0.1 - - [22/May/2025 17:27:36] "GET /tablas/descargar/Adquisicion%20de%20Inmuebles_V2_20022025%20(4).xlsx HTTP/1.1" 404 -
127.0.0.1 - - [22/May/2025 17:27:59] "GET /tablas/descargar/geo-3%20(5)%20(1)%20(3).kml HTTP/1.1" 404 -
 * Detected change in 'C:\\Users\\francisco.contreras\\Desktop\\jupyter-projects\\notebooks\\MAYA-Modular\\app\\.ipynb_checkpoints\\tablas_busqueda-checkpoint.py', reloading
 * Restarting with stat
 * Debugger is active!
 * Debugger PIN: 828-147-444
 * Detected change in 'C:\\Users\\francisco.contreras\\Desktop\\jupyter-projects\\notebooks\\MAYA-Modular\\app\\tablas_busqueda.py', reloading
 * Restarting with stat
 * Debugger is active!
 * Debugger PIN: 828-147-444
127.0.0.1 - - [22/May/2025 17:31:29] "GET /tablas/ HTTP/1.1" 200 -
127.0.0.1 - - [22/May/2025 17:31:30] "GET /tablas/generar_tabla HTTP/1.1" 200 -
127.0.0.1 - - [22/May/2025 17:31:31] "GET /tablas/descargar/Publica%20(3)%20(4).bpmn HTTP/1.1" 200 -
127.0.0.1 - - [22/May/2025 17:35:33] "GET /tablas/descargar/ipconfig_Francisco_CL%20(3).out HTTP/1.1" 200 -
127.0.0.1 - - [22/May/2025 17:35:42] "GET /tablas/ HTTP/1.1" 200 -
127.0.0.1 - - [22/May/2025 17:35:43] "GET /tablas/generar_tabla HTTP/1.1" 200 -
 * Detected change in 'C:\\Users\\francisco.contreras\\Desktop\\jupyter-projects\\notebooks\\MAYA-Modular\\app\\main.py', reloading
 * Restarting with stat
Traceback (most recent call last):
  File "<frozen runpy>", line 198, in _run_module_as_main
  File "<frozen runpy>", line 88, in _run_code
  File "C:\Users\francisco.contreras\Desktop\jupyter-projects\notebooks\MAYA-Modular\app\main.py", line 4, in <module>
    from app.functions import extract_and_store_documents
ModuleNotFoundError: No module named 'app.functions'
